2025-04-23 22:30:52,194 - INFO - Start polling
2025-04-23 22:30:52,398 - INFO - Run polling for bot @audio_cut_huawei_bot id=7828398845 - 'Audio for Huawei watch GT 4'
2025-04-23 22:31:04,130 - INFO - Update id=350515979 is handled. Duration 189 ms by bot id=7828398845
2025-04-23 22:31:06,290 - INFO - Начата обработка видео https://youtu.be/W_Hkge5qYl4?si=PK79Ua45CnOJzj9j со скоростью 1.5
2025-04-23 22:31:06,430 - INFO - Update id=350515980 is handled. Duration 140 ms by bot id=7828398845
2025-04-23 22:31:08,422 - INFO - Update id=350515981 is handled. Duration 84 ms by bot id=7828398845
2025-04-23 22:31:10,050 - INFO - Update id=350515982 is handled. Duration 380 ms by bot id=7828398845
2025-04-23 22:31:10,676 - ERROR - Неизвестная ошибка: no running event loop
2025-04-23 22:31:10,680 - INFO - Начата обработка видео https://youtu.be/W_Hkge5qYl4?si=PK79Ua45CnOJzj9j со скоростью 1.5
2025-04-23 22:31:12,983 - INFO - Update id=350515983 is handled. Duration 317 ms by bot id=7828398845
2025-04-23 22:31:13,995 - INFO - Update id=350515984 is handled. Duration 278 ms by bot id=7828398845
2025-04-23 22:31:14,462 - ERROR - Неизвестная ошибка: no running event loop
2025-04-23 22:31:14,464 - INFO - Начата обработка видео https://youtu.be/W_Hkge5qYl4?si=PK79Ua45CnOJzj9j со скоростью 1.75
2025-04-23 22:31:18,381 - ERROR - Неизвестная ошибка: no running event loop
2025-04-23 22:32:35,403 - INFO - Polling stopped
2025-04-23 22:32:35,668 - INFO - Polling stopped for bot @audio_cut_huawei_bot id=7828398845 - 'Audio for Huawei watch GT 4'
2025-04-23 22:32:39,794 - INFO - Start polling
2025-04-23 22:32:39,968 - INFO - Run polling for bot @audio_cut_huawei_bot id=7828398845 - 'Audio for Huawei watch GT 4'
2025-04-23 22:32:49,793 - INFO - Update id=350515985 is handled. Duration 261 ms by bot id=7828398845
2025-04-23 22:32:50,888 - INFO - Начата обработка видео https://youtu.be/W_Hkge5qYl4?si=PK79Ua45CnOJzj9j со скоростью 1.75
2025-04-23 22:32:51,038 - INFO - Update id=350515986 is handled. Duration 149 ms by bot id=7828398845
2025-04-23 22:32:55,627 - INFO - Update id=350515987 is handled. Duration 2859 ms by bot id=7828398845
2025-04-23 22:32:57,528 - INFO - Update id=350515988 is handled. Duration 710 ms by bot id=7828398845
2025-04-23 22:33:16,713 - INFO - Обработка https://youtu.be/W_Hkge5qYl4?si=PK79Ua45CnOJzj9j завершена успешно
2025-04-23 22:33:16,716 - INFO - Начата обработка видео https://youtu.be/W_Hkge5qYl4?si=PK79Ua45CnOJzj9j со скоростью 1.25
2025-04-23 22:33:46,406 - INFO - Обработка https://youtu.be/W_Hkge5qYl4?si=PK79Ua45CnOJzj9j завершена успешно
2025-04-23 22:35:33,958 - INFO - Polling stopped
2025-04-23 22:35:34,218 - INFO - Polling stopped for bot @audio_cut_huawei_bot id=7828398845 - 'Audio for Huawei watch GT 4'
2025-04-23 22:35:38,530 - INFO - Start polling
2025-04-23 22:35:38,734 - INFO - Run polling for bot @audio_cut_huawei_bot id=7828398845 - 'Audio for Huawei watch GT 4'
2025-04-23 22:36:03,909 - INFO - Update id=350515989 is handled. Duration 197 ms by bot id=7828398845
2025-04-23 22:36:05,616 - INFO - Начата обработка видео https://youtu.be/zE97u_gqeGA?si=woHbjYoJla1oBsoG со скоростью 1.25
2025-04-23 22:36:05,768 - INFO - Update id=350515990 is handled. Duration 152 ms by bot id=7828398845
2025-04-23 22:36:10,005 - ERROR - Task exception was never retrieved
future: <Task finished name='Task-21' coro=<Bot.edit_message_text() done, defined at C:\Users\Evgen\AppData\Local\Programs\Python\Python313\Lib\site-packages\aiogram\client\bot.py:1535> exception=1 validation error for EditMessageText
business_connection_id
  Input should be a valid string [type=string_type, input_value=6156605396, input_type=int]
    For further information visit https://errors.pydantic.dev/2.9/v/string_type>
Traceback (most recent call last):
  File "C:\Users\Evgen\AppData\Local\Programs\Python\Python313\Lib\site-packages\aiogram\client\bot.py", line 1572, in edit_message_text
    call = EditMessageText(
        text=text,
    ...<8 lines>...
        disable_web_page_preview=disable_web_page_preview,
    )
  File "C:\Users\Evgen\AppData\Local\Programs\Python\Python313\Lib\site-packages\pydantic\main.py", line 212, in __init__
    validated_self = self.__pydantic_validator__.validate_python(data, self_instance=self)
pydantic_core._pydantic_core.ValidationError: 1 validation error for EditMessageText
business_connection_id
  Input should be a valid string [type=string_type, input_value=6156605396, input_type=int]
    For further information visit https://errors.pydantic.dev/2.9/v/string_type
2025-04-23 22:36:10,084 - ERROR - Task exception was never retrieved
future: <Task finished name='Task-22' coro=<Bot.edit_message_text() done, defined at C:\Users\Evgen\AppData\Local\Programs\Python\Python313\Lib\site-packages\aiogram\client\bot.py:1535> exception=1 validation error for EditMessageText
business_connection_id
  Input should be a valid string [type=string_type, input_value=6156605396, input_type=int]
    For further information visit https://errors.pydantic.dev/2.9/v/string_type>
Traceback (most recent call last):
  File "C:\Users\Evgen\AppData\Local\Programs\Python\Python313\Lib\site-packages\aiogram\client\bot.py", line 1572, in edit_message_text
    call = EditMessageText(
        text=text,
    ...<8 lines>...
        disable_web_page_preview=disable_web_page_preview,
    )
  File "C:\Users\Evgen\AppData\Local\Programs\Python\Python313\Lib\site-packages\pydantic\main.py", line 212, in __init__
    validated_self = self.__pydantic_validator__.validate_python(data, self_instance=self)
pydantic_core._pydantic_core.ValidationError: 1 validation error for EditMessageText
business_connection_id
  Input should be a valid string [type=string_type, input_value=6156605396, input_type=int]
    For further information visit https://errors.pydantic.dev/2.9/v/string_type
2025-04-23 22:36:10,244 - ERROR - Task exception was never retrieved
future: <Task finished name='Task-23' coro=<Bot.edit_message_text() done, defined at C:\Users\Evgen\AppData\Local\Programs\Python\Python313\Lib\site-packages\aiogram\client\bot.py:1535> exception=1 validation error for EditMessageText
business_connection_id
  Input should be a valid string [type=string_type, input_value=6156605396, input_type=int]
    For further information visit https://errors.pydantic.dev/2.9/v/string_type>
Traceback (most recent call last):
  File "C:\Users\Evgen\AppData\Local\Programs\Python\Python313\Lib\site-packages\aiogram\client\bot.py", line 1572, in edit_message_text
    call = EditMessageText(
        text=text,
    ...<8 lines>...
        disable_web_page_preview=disable_web_page_preview,
    )
  File "C:\Users\Evgen\AppData\Local\Programs\Python\Python313\Lib\site-packages\pydantic\main.py", line 212, in __init__
    validated_self = self.__pydantic_validator__.validate_python(data, self_instance=self)
pydantic_core._pydantic_core.ValidationError: 1 validation error for EditMessageText
business_connection_id
  Input should be a valid string [type=string_type, input_value=6156605396, input_type=int]
    For further information visit https://errors.pydantic.dev/2.9/v/string_type
2025-04-23 22:36:10,330 - ERROR - Task exception was never retrieved
future: <Task finished name='Task-24' coro=<Bot.edit_message_text() done, defined at C:\Users\Evgen\AppData\Local\Programs\Python\Python313\Lib\site-packages\aiogram\client\bot.py:1535> exception=1 validation error for EditMessageText
business_connection_id
  Input should be a valid string [type=string_type, input_value=6156605396, input_type=int]
    For further information visit https://errors.pydantic.dev/2.9/v/string_type>
Traceback (most recent call last):
  File "C:\Users\Evgen\AppData\Local\Programs\Python\Python313\Lib\site-packages\aiogram\client\bot.py", line 1572, in edit_message_text
    call = EditMessageText(
        text=text,
    ...<8 lines>...
        disable_web_page_preview=disable_web_page_preview,
    )
  File "C:\Users\Evgen\AppData\Local\Programs\Python\Python313\Lib\site-packages\pydantic\main.py", line 212, in __init__
    validated_self = self.__pydantic_validator__.validate_python(data, self_instance=self)
pydantic_core._pydantic_core.ValidationError: 1 validation error for EditMessageText
business_connection_id
  Input should be a valid string [type=string_type, input_value=6156605396, input_type=int]
    For further information visit https://errors.pydantic.dev/2.9/v/string_type
2025-04-23 22:36:10,432 - ERROR - Task exception was never retrieved
future: <Task finished name='Task-25' coro=<Bot.edit_message_text() done, defined at C:\Users\Evgen\AppData\Local\Programs\Python\Python313\Lib\site-packages\aiogram\client\bot.py:1535> exception=1 validation error for EditMessageText
business_connection_id
  Input should be a valid string [type=string_type, input_value=6156605396, input_type=int]
    For further information visit https://errors.pydantic.dev/2.9/v/string_type>
Traceback (most recent call last):
  File "C:\Users\Evgen\AppData\Local\Programs\Python\Python313\Lib\site-packages\aiogram\client\bot.py", line 1572, in edit_message_text
    call = EditMessageText(
        text=text,
    ...<8 lines>...
        disable_web_page_preview=disable_web_page_preview,
    )
  File "C:\Users\Evgen\AppData\Local\Programs\Python\Python313\Lib\site-packages\pydantic\main.py", line 212, in __init__
    validated_self = self.__pydantic_validator__.validate_python(data, self_instance=self)
pydantic_core._pydantic_core.ValidationError: 1 validation error for EditMessageText
business_connection_id
  Input should be a valid string [type=string_type, input_value=6156605396, input_type=int]
    For further information visit https://errors.pydantic.dev/2.9/v/string_type
2025-04-23 22:36:18,575 - INFO - Обработка https://youtu.be/zE97u_gqeGA?si=woHbjYoJla1oBsoG завершена успешно
2025-04-23 22:37:57,544 - INFO - Update id=350515991 is handled. Duration 156 ms by bot id=7828398845
2025-04-23 22:38:00,877 - INFO - Начата обработка видео https://youtu.be/BFr5cnatXpU?si=ll4P5WoyzE2t4q8P со скоростью 1.5
2025-04-23 22:38:00,998 - INFO - Update id=350515992 is handled. Duration 121 ms by bot id=7828398845
2025-04-23 22:38:17,820 - ERROR - Task exception was never retrieved
future: <Task finished name='Task-57' coro=<Bot.edit_message_text() done, defined at C:\Users\Evgen\AppData\Local\Programs\Python\Python313\Lib\site-packages\aiogram\client\bot.py:1535> exception=1 validation error for EditMessageText
business_connection_id
  Input should be a valid string [type=string_type, input_value=6156605396, input_type=int]
    For further information visit https://errors.pydantic.dev/2.9/v/string_type>
Traceback (most recent call last):
  File "C:\Users\Evgen\AppData\Local\Programs\Python\Python313\Lib\site-packages\aiogram\client\bot.py", line 1572, in edit_message_text
    call = EditMessageText(
        text=text,
    ...<8 lines>...
        disable_web_page_preview=disable_web_page_preview,
    )
  File "C:\Users\Evgen\AppData\Local\Programs\Python\Python313\Lib\site-packages\pydantic\main.py", line 212, in __init__
    validated_self = self.__pydantic_validator__.validate_python(data, self_instance=self)
pydantic_core._pydantic_core.ValidationError: 1 validation error for EditMessageText
business_connection_id
  Input should be a valid string [type=string_type, input_value=6156605396, input_type=int]
    For further information visit https://errors.pydantic.dev/2.9/v/string_type
2025-04-23 22:38:19,619 - ERROR - Task exception was never retrieved
future: <Task finished name='Task-58' coro=<Bot.edit_message_text() done, defined at C:\Users\Evgen\AppData\Local\Programs\Python\Python313\Lib\site-packages\aiogram\client\bot.py:1535> exception=1 validation error for EditMessageText
business_connection_id
  Input should be a valid string [type=string_type, input_value=6156605396, input_type=int]
    For further information visit https://errors.pydantic.dev/2.9/v/string_type>
Traceback (most recent call last):
  File "C:\Users\Evgen\AppData\Local\Programs\Python\Python313\Lib\site-packages\aiogram\client\bot.py", line 1572, in edit_message_text
    call = EditMessageText(
        text=text,
    ...<8 lines>...
        disable_web_page_preview=disable_web_page_preview,
    )
  File "C:\Users\Evgen\AppData\Local\Programs\Python\Python313\Lib\site-packages\pydantic\main.py", line 212, in __init__
    validated_self = self.__pydantic_validator__.validate_python(data, self_instance=self)
pydantic_core._pydantic_core.ValidationError: 1 validation error for EditMessageText
business_connection_id
  Input should be a valid string [type=string_type, input_value=6156605396, input_type=int]
    For further information visit https://errors.pydantic.dev/2.9/v/string_type
2025-04-23 22:38:22,163 - ERROR - Task exception was never retrieved
future: <Task finished name='Task-60' coro=<Bot.edit_message_text() done, defined at C:\Users\Evgen\AppData\Local\Programs\Python\Python313\Lib\site-packages\aiogram\client\bot.py:1535> exception=1 validation error for EditMessageText
business_connection_id
  Input should be a valid string [type=string_type, input_value=6156605396, input_type=int]
    For further information visit https://errors.pydantic.dev/2.9/v/string_type>
Traceback (most recent call last):
  File "C:\Users\Evgen\AppData\Local\Programs\Python\Python313\Lib\site-packages\aiogram\client\bot.py", line 1572, in edit_message_text
    call = EditMessageText(
        text=text,
    ...<8 lines>...
        disable_web_page_preview=disable_web_page_preview,
    )
  File "C:\Users\Evgen\AppData\Local\Programs\Python\Python313\Lib\site-packages\pydantic\main.py", line 212, in __init__
    validated_self = self.__pydantic_validator__.validate_python(data, self_instance=self)
pydantic_core._pydantic_core.ValidationError: 1 validation error for EditMessageText
business_connection_id
  Input should be a valid string [type=string_type, input_value=6156605396, input_type=int]
    For further information visit https://errors.pydantic.dev/2.9/v/string_type
2025-04-23 22:38:24,777 - ERROR - Task exception was never retrieved
future: <Task finished name='Task-61' coro=<Bot.edit_message_text() done, defined at C:\Users\Evgen\AppData\Local\Programs\Python\Python313\Lib\site-packages\aiogram\client\bot.py:1535> exception=1 validation error for EditMessageText
business_connection_id
  Input should be a valid string [type=string_type, input_value=6156605396, input_type=int]
    For further information visit https://errors.pydantic.dev/2.9/v/string_type>
Traceback (most recent call last):
  File "C:\Users\Evgen\AppData\Local\Programs\Python\Python313\Lib\site-packages\aiogram\client\bot.py", line 1572, in edit_message_text
    call = EditMessageText(
        text=text,
    ...<8 lines>...
        disable_web_page_preview=disable_web_page_preview,
    )
  File "C:\Users\Evgen\AppData\Local\Programs\Python\Python313\Lib\site-packages\pydantic\main.py", line 212, in __init__
    validated_self = self.__pydantic_validator__.validate_python(data, self_instance=self)
pydantic_core._pydantic_core.ValidationError: 1 validation error for EditMessageText
business_connection_id
  Input should be a valid string [type=string_type, input_value=6156605396, input_type=int]
    For further information visit https://errors.pydantic.dev/2.9/v/string_type
2025-04-23 22:38:26,758 - ERROR - Task exception was never retrieved
future: <Task finished name='Task-62' coro=<Bot.edit_message_text() done, defined at C:\Users\Evgen\AppData\Local\Programs\Python\Python313\Lib\site-packages\aiogram\client\bot.py:1535> exception=1 validation error for EditMessageText
business_connection_id
  Input should be a valid string [type=string_type, input_value=6156605396, input_type=int]
    For further information visit https://errors.pydantic.dev/2.9/v/string_type>
Traceback (most recent call last):
  File "C:\Users\Evgen\AppData\Local\Programs\Python\Python313\Lib\site-packages\aiogram\client\bot.py", line 1572, in edit_message_text
    call = EditMessageText(
        text=text,
    ...<8 lines>...
        disable_web_page_preview=disable_web_page_preview,
    )
  File "C:\Users\Evgen\AppData\Local\Programs\Python\Python313\Lib\site-packages\pydantic\main.py", line 212, in __init__
    validated_self = self.__pydantic_validator__.validate_python(data, self_instance=self)
pydantic_core._pydantic_core.ValidationError: 1 validation error for EditMessageText
business_connection_id
  Input should be a valid string [type=string_type, input_value=6156605396, input_type=int]
    For further information visit https://errors.pydantic.dev/2.9/v/string_type
2025-04-23 22:38:28,513 - ERROR - Task exception was never retrieved
future: <Task finished name='Task-63' coro=<Bot.edit_message_text() done, defined at C:\Users\Evgen\AppData\Local\Programs\Python\Python313\Lib\site-packages\aiogram\client\bot.py:1535> exception=1 validation error for EditMessageText
business_connection_id
  Input should be a valid string [type=string_type, input_value=6156605396, input_type=int]
    For further information visit https://errors.pydantic.dev/2.9/v/string_type>
Traceback (most recent call last):
  File "C:\Users\Evgen\AppData\Local\Programs\Python\Python313\Lib\site-packages\aiogram\client\bot.py", line 1572, in edit_message_text
    call = EditMessageText(
        text=text,
    ...<8 lines>...
        disable_web_page_preview=disable_web_page_preview,
    )
  File "C:\Users\Evgen\AppData\Local\Programs\Python\Python313\Lib\site-packages\pydantic\main.py", line 212, in __init__
    validated_self = self.__pydantic_validator__.validate_python(data, self_instance=self)
pydantic_core._pydantic_core.ValidationError: 1 validation error for EditMessageText
business_connection_id
  Input should be a valid string [type=string_type, input_value=6156605396, input_type=int]
    For further information visit https://errors.pydantic.dev/2.9/v/string_type
2025-04-23 22:38:29,514 - ERROR - Task exception was never retrieved
future: <Task finished name='Task-64' coro=<Bot.edit_message_text() done, defined at C:\Users\Evgen\AppData\Local\Programs\Python\Python313\Lib\site-packages\aiogram\client\bot.py:1535> exception=1 validation error for EditMessageText
business_connection_id
  Input should be a valid string [type=string_type, input_value=6156605396, input_type=int]
    For further information visit https://errors.pydantic.dev/2.9/v/string_type>
Traceback (most recent call last):
  File "C:\Users\Evgen\AppData\Local\Programs\Python\Python313\Lib\site-packages\aiogram\client\bot.py", line 1572, in edit_message_text
    call = EditMessageText(
        text=text,
    ...<8 lines>...
        disable_web_page_preview=disable_web_page_preview,
    )
  File "C:\Users\Evgen\AppData\Local\Programs\Python\Python313\Lib\site-packages\pydantic\main.py", line 212, in __init__
    validated_self = self.__pydantic_validator__.validate_python(data, self_instance=self)
pydantic_core._pydantic_core.ValidationError: 1 validation error for EditMessageText
business_connection_id
  Input should be a valid string [type=string_type, input_value=6156605396, input_type=int]
    For further information visit https://errors.pydantic.dev/2.9/v/string_type
2025-04-23 22:38:40,243 - INFO - Обработка https://youtu.be/BFr5cnatXpU?si=ll4P5WoyzE2t4q8P завершена успешно
2025-04-23 22:40:40,641 - INFO - Polling stopped
2025-04-23 22:40:40,893 - INFO - Polling stopped for bot @audio_cut_huawei_bot id=7828398845 - 'Audio for Huawei watch GT 4'
2025-04-23 22:40:44,721 - INFO - Start polling
2025-04-23 22:40:44,940 - INFO - Run polling for bot @audio_cut_huawei_bot id=7828398845 - 'Audio for Huawei watch GT 4'
2025-04-23 22:40:51,251 - INFO - Update id=350515993 is handled. Duration 155 ms by bot id=7828398845
2025-04-23 22:40:52,355 - INFO - Начата обработка видео https://youtu.be/BFr5cnatXpU?si=ll4P5WoyzE2t4q8P со скоростью 1.0
2025-04-23 22:40:52,467 - INFO - Update id=350515994 is handled. Duration 112 ms by bot id=7828398845
2025-04-23 22:40:56,613 - ERROR - Task exception was never retrieved
future: <Task finished name='Task-19' coro=<Bot.edit_message_text() done, defined at C:\Users\Evgen\AppData\Local\Programs\Python\Python313\Lib\site-packages\aiogram\client\bot.py:1535> exception=1 validation error for EditMessageText
business_connection_id
  Input should be a valid string [type=string_type, input_value=6156605396, input_type=int]
    For further information visit https://errors.pydantic.dev/2.9/v/string_type>
Traceback (most recent call last):
  File "C:\Users\Evgen\AppData\Local\Programs\Python\Python313\Lib\site-packages\aiogram\client\bot.py", line 1572, in edit_message_text
    call = EditMessageText(
        text=text,
    ...<8 lines>...
        disable_web_page_preview=disable_web_page_preview,
    )
  File "C:\Users\Evgen\AppData\Local\Programs\Python\Python313\Lib\site-packages\pydantic\main.py", line 212, in __init__
    validated_self = self.__pydantic_validator__.validate_python(data, self_instance=self)
pydantic_core._pydantic_core.ValidationError: 1 validation error for EditMessageText
business_connection_id
  Input should be a valid string [type=string_type, input_value=6156605396, input_type=int]
    For further information visit https://errors.pydantic.dev/2.9/v/string_type
2025-04-23 22:40:56,661 - ERROR - Task exception was never retrieved
future: <Task finished name='Task-20' coro=<Bot.edit_message_text() done, defined at C:\Users\Evgen\AppData\Local\Programs\Python\Python313\Lib\site-packages\aiogram\client\bot.py:1535> exception=1 validation error for EditMessageText
business_connection_id
  Input should be a valid string [type=string_type, input_value=6156605396, input_type=int]
    For further information visit https://errors.pydantic.dev/2.9/v/string_type>
Traceback (most recent call last):
  File "C:\Users\Evgen\AppData\Local\Programs\Python\Python313\Lib\site-packages\aiogram\client\bot.py", line 1572, in edit_message_text
    call = EditMessageText(
        text=text,
    ...<8 lines>...
        disable_web_page_preview=disable_web_page_preview,
    )
  File "C:\Users\Evgen\AppData\Local\Programs\Python\Python313\Lib\site-packages\pydantic\main.py", line 212, in __init__
    validated_self = self.__pydantic_validator__.validate_python(data, self_instance=self)
pydantic_core._pydantic_core.ValidationError: 1 validation error for EditMessageText
business_connection_id
  Input should be a valid string [type=string_type, input_value=6156605396, input_type=int]
    For further information visit https://errors.pydantic.dev/2.9/v/string_type
2025-04-23 22:40:56,799 - ERROR - Task exception was never retrieved
future: <Task finished name='Task-21' coro=<Bot.edit_message_text() done, defined at C:\Users\Evgen\AppData\Local\Programs\Python\Python313\Lib\site-packages\aiogram\client\bot.py:1535> exception=1 validation error for EditMessageText
business_connection_id
  Input should be a valid string [type=string_type, input_value=6156605396, input_type=int]
    For further information visit https://errors.pydantic.dev/2.9/v/string_type>
Traceback (most recent call last):
  File "C:\Users\Evgen\AppData\Local\Programs\Python\Python313\Lib\site-packages\aiogram\client\bot.py", line 1572, in edit_message_text
    call = EditMessageText(
        text=text,
    ...<8 lines>...
        disable_web_page_preview=disable_web_page_preview,
    )
  File "C:\Users\Evgen\AppData\Local\Programs\Python\Python313\Lib\site-packages\pydantic\main.py", line 212, in __init__
    validated_self = self.__pydantic_validator__.validate_python(data, self_instance=self)
pydantic_core._pydantic_core.ValidationError: 1 validation error for EditMessageText
business_connection_id
  Input should be a valid string [type=string_type, input_value=6156605396, input_type=int]
    For further information visit https://errors.pydantic.dev/2.9/v/string_type
2025-04-23 22:40:56,988 - ERROR - Task exception was never retrieved
future: <Task finished name='Task-22' coro=<Bot.edit_message_text() done, defined at C:\Users\Evgen\AppData\Local\Programs\Python\Python313\Lib\site-packages\aiogram\client\bot.py:1535> exception=1 validation error for EditMessageText
business_connection_id
  Input should be a valid string [type=string_type, input_value=6156605396, input_type=int]
    For further information visit https://errors.pydantic.dev/2.9/v/string_type>
Traceback (most recent call last):
  File "C:\Users\Evgen\AppData\Local\Programs\Python\Python313\Lib\site-packages\aiogram\client\bot.py", line 1572, in edit_message_text
    call = EditMessageText(
        text=text,
    ...<8 lines>...
        disable_web_page_preview=disable_web_page_preview,
    )
  File "C:\Users\Evgen\AppData\Local\Programs\Python\Python313\Lib\site-packages\pydantic\main.py", line 212, in __init__
    validated_self = self.__pydantic_validator__.validate_python(data, self_instance=self)
pydantic_core._pydantic_core.ValidationError: 1 validation error for EditMessageText
business_connection_id
  Input should be a valid string [type=string_type, input_value=6156605396, input_type=int]
    For further information visit https://errors.pydantic.dev/2.9/v/string_type
2025-04-23 22:40:57,196 - ERROR - Task exception was never retrieved
future: <Task finished name='Task-23' coro=<Bot.edit_message_text() done, defined at C:\Users\Evgen\AppData\Local\Programs\Python\Python313\Lib\site-packages\aiogram\client\bot.py:1535> exception=1 validation error for EditMessageText
business_connection_id
  Input should be a valid string [type=string_type, input_value=6156605396, input_type=int]
    For further information visit https://errors.pydantic.dev/2.9/v/string_type>
Traceback (most recent call last):
  File "C:\Users\Evgen\AppData\Local\Programs\Python\Python313\Lib\site-packages\aiogram\client\bot.py", line 1572, in edit_message_text
    call = EditMessageText(
        text=text,
    ...<8 lines>...
        disable_web_page_preview=disable_web_page_preview,
    )
  File "C:\Users\Evgen\AppData\Local\Programs\Python\Python313\Lib\site-packages\pydantic\main.py", line 212, in __init__
    validated_self = self.__pydantic_validator__.validate_python(data, self_instance=self)
pydantic_core._pydantic_core.ValidationError: 1 validation error for EditMessageText
business_connection_id
  Input should be a valid string [type=string_type, input_value=6156605396, input_type=int]
    For further information visit https://errors.pydantic.dev/2.9/v/string_type
2025-04-23 22:40:57,434 - ERROR - Task exception was never retrieved
future: <Task finished name='Task-24' coro=<Bot.edit_message_text() done, defined at C:\Users\Evgen\AppData\Local\Programs\Python\Python313\Lib\site-packages\aiogram\client\bot.py:1535> exception=1 validation error for EditMessageText
business_connection_id
  Input should be a valid string [type=string_type, input_value=6156605396, input_type=int]
    For further information visit https://errors.pydantic.dev/2.9/v/string_type>
Traceback (most recent call last):
  File "C:\Users\Evgen\AppData\Local\Programs\Python\Python313\Lib\site-packages\aiogram\client\bot.py", line 1572, in edit_message_text
    call = EditMessageText(
        text=text,
    ...<8 lines>...
        disable_web_page_preview=disable_web_page_preview,
    )
  File "C:\Users\Evgen\AppData\Local\Programs\Python\Python313\Lib\site-packages\pydantic\main.py", line 212, in __init__
    validated_self = self.__pydantic_validator__.validate_python(data, self_instance=self)
pydantic_core._pydantic_core.ValidationError: 1 validation error for EditMessageText
business_connection_id
  Input should be a valid string [type=string_type, input_value=6156605396, input_type=int]
    For further information visit https://errors.pydantic.dev/2.9/v/string_type
2025-04-23 22:40:57,460 - INFO - Загрузка завершена для chat_id 6156605396
2025-04-23 22:40:57,606 - ERROR - Неизвестная ошибка: 1 validation error for EditMessageText
business_connection_id
  Input should be a valid string [type=string_type, input_value=6156605396, input_type=int]
    For further information visit https://errors.pydantic.dev/2.9/v/string_type
2025-04-23 22:45:54,525 - INFO - Polling stopped
2025-04-23 22:45:54,791 - INFO - Polling stopped for bot @audio_cut_huawei_bot id=7828398845 - 'Audio for Huawei watch GT 4'
2025-04-23 22:45:58,783 - INFO - Start polling
2025-04-23 22:45:58,987 - INFO - Run polling for bot @audio_cut_huawei_bot id=7828398845 - 'Audio for Huawei watch GT 4'
2025-04-23 22:46:10,863 - INFO - Update id=350515995 is handled. Duration 233 ms by bot id=7828398845
2025-04-23 22:46:12,001 - INFO - Начата обработка видео https://youtu.be/BFr5cnatXpU?si=ll4P5WoyzE2t4q8P со скоростью 1.0
2025-04-23 22:46:12,149 - INFO - Update id=350515996 is handled. Duration 148 ms by bot id=7828398845
2025-04-23 22:46:16,070 - ERROR - Неизвестная ошибка: unsupported operand type(s) for +: 'int' and 'str'
2025-04-23 22:49:54,248 - INFO - Polling stopped
2025-04-23 22:49:54,502 - INFO - Polling stopped for bot @audio_cut_huawei_bot id=7828398845 - 'Audio for Huawei watch GT 4'
2025-04-23 22:49:58,451 - INFO - Start polling
2025-04-23 22:49:58,615 - INFO - Run polling for bot @audio_cut_huawei_bot id=7828398845 - 'Audio for Huawei watch GT 4'
2025-04-23 22:50:05,739 - INFO - Update id=350515997 is handled. Duration 250 ms by bot id=7828398845
2025-04-23 22:50:06,856 - INFO - Начата обработка видео https://youtu.be/BFr5cnatXpU?si=ll4P5WoyzE2t4q8P со скоростью 1.0
2025-04-23 22:50:07,055 - INFO - Update id=350515998 is handled. Duration 199 ms by bot id=7828398845
2025-04-23 22:50:12,804 - INFO - Загрузка завершена для chat_id 6156605396
2025-04-23 22:50:28,950 - INFO - Обработка https://youtu.be/BFr5cnatXpU?si=ll4P5WoyzE2t4q8P завершена успешно
2025-04-23 22:51:03,511 - INFO - Update id=350515999 is handled. Duration 187 ms by bot id=7828398845
2025-04-23 22:51:07,278 - INFO - Начата обработка видео https://youtu.be/f9wAAvuruQU?si=AmvUGCdku6q7B3GM со скоростью 1.0
2025-04-23 22:51:07,497 - INFO - Update id=350516000 is handled. Duration 219 ms by bot id=7828398845
2025-04-23 22:51:13,089 - INFO - Загрузка завершена для chat_id 6156605396
2025-04-23 22:51:22,728 - INFO - Update id=350516001 is handled. Duration 77 ms by bot id=7828398845
2025-04-23 22:51:25,091 - INFO - Update id=350516002 is handled. Duration 118 ms by bot id=7828398845
2025-04-23 22:51:40,684 - INFO - Обработка https://youtu.be/f9wAAvuruQU?si=AmvUGCdku6q7B3GM завершена успешно
2025-04-23 22:51:40,687 - INFO - Начата обработка видео https://youtu.be/cfQT4kF4O_A?si=uuL76X2YIiyXPg7O со скоростью 1.25
2025-04-23 22:51:45,118 - INFO - Загрузка завершена для chat_id 6156605396
2025-04-23 22:51:51,292 - INFO - Обработка https://youtu.be/cfQT4kF4O_A?si=uuL76X2YIiyXPg7O завершена успешно
2025-04-23 22:52:25,417 - INFO - Polling stopped
2025-04-23 22:52:25,683 - INFO - Polling stopped for bot @audio_cut_huawei_bot id=7828398845 - 'Audio for Huawei watch GT 4'
